Workbook
Name Slicer_category: #N/A
Name Slicer_customer_segment: #N/A
Name Slicer_delivery_status: #N/A
Name Slicer_payment_method: #N/A

Sheet blinkit_order_items
A1: order_id | B1: product_id | C1: quantity | D1: unit_price
A2: 1961864118 | B2: 642612 | C2: 3 | D2: 517.03
A3: 1549769649 | B3: 378676 | C3: 1 | D3: 881.42
A4: 9185164487 | B4: 741341 | C4: 2 | D4: 923.84
A5: 9644738826 | B5: 561860 | C5: 1 | D5: 874.78
A6: 5427684290 | B6: 602241 | C6: 2 | D6: 976.55
A7: 3265154092 | B7: 681063 | C7: 1 | D7: 321.28
A8: 4898355547 | B8: 56589 | C8: 3 | D8: 517.77
A9: 6568151549 | B9: 500739 | C9: 2 | D9: 359.98
A10: 6006693867 | B10: 490939 | C10: 1 | D10: 80.25
A11: 374186990 | B11: 760828 | C11: 2 | D11: 563.45
A12: 4455336265 | B12: 753354 | C12: 3 | D12: 423.56
A13: 3539286337 | B13: 684939 | C13: 1 | D13: 727.95
... A5001: 2494813730 | B5001: 136533 | C5001: 1 | D5001: 826.21

Sheet blinkit_products
A1: product_id | B1: product_name | C1: category | D1: brand | E1: price | F1: mrp | G1: margin_percentage | H1: shelf_life_days | I1: min_stock_level | J1: max_stock_level
A2: 153019 | B2: Onions | C2: Fruits & Vegetables | D2: Aurora LLC | E2: 947.95 | F2: 1263.93 | G2: 25 | H2: 3 | I2: 13 | J2: 88
A3: 11422 | B3: Potatoes | C3: Fruits & Vegetables | D3: Ramaswamy-Tata | E3: 127.16 | F3: 169.55 | G3: 25 | H3: 3 | I3: 20 | J3: 65
A4: 669378 | B4: Potatoes | C4: Fruits & Vegetables | D4: Chadha and Sons | E4: 212.14 | F4: 282.85 | G4: 25 | H4: 3 | I4: 23 | J4: 70
A5: 848226 | B5: Tomatoes | C5: Fruits & Vegetables | D5: Barad and Sons | E5: 209.59 | F5: 279.45 | G5: 25 | H5: 3 | I5: 10 | J5: 51
A6: 890623 | B6: Onions | C6: Fruits & Vegetables | D6: Sangha, Nagar and Varty | E6: 354.52 | F6: 472.69 | G6: 25 | H6: 3 | I6: 27 | J6: 55
A7: 965755 | B7: Bananas | C7: Fruits & Vegetables | D7: Doshi, Sarraf and Sama | E7: 532.57 | F7: 710.09 | G7: 25 | H7: 3 | I7: 21 | J7: 91
A8: 222892 | B8: Tomatoes | C8: Fruits & Vegetables | D8: Ramakrishnan-Ghose | E8: 869.22 | F8: 1158.96 | G8: 25 | H8: 3 | I8: 28 | J8: 88
A9: 516376 | B9: Onions | C9: Fruits & Vegetables | D9: Agarwal-Dhar | E9: 877.43 | F9: 1169.91 | G9: 25 | H9: 3 | I9: 21 | J9: 71
A10: 39154 | B10: Mangoes | C10: Fruits & Vegetables | D10: Suresh, Bose and Bajwa | E10: 946.86 | F10: 1262.48 | G10: 25 | H10: 3 | I10: 21 | J10: 84
A11: 34186 | B11: Mangoes | C11: Fruits & Vegetables | D11: Mandal-Kar | E11: 925.65 | F11: 1234.2 | G11: 25 | H11: 3 | I11: 27 | J11: 74
A12: 196719 | B12: Bananas | C12: Fruits & Vegetables | D12: Yogi Group | E12: 217.5 | F12: 290 | G12: 25 | H12: 3 | I12: 15 | J12: 91
A13: 478531 | B13: Carrots | C13: Fruits & Vegetables | D13: Uppal Group | E13: 825.46 | F13: 1100.61 | G13: 25 | H13: 3 | I13: 24 | J13: 90
... A269: 114414 | B269: Vitamins | C269: Pharmacy | D269: Kara-Golla | E269: 832.06 | F269: 1040.07 | G269: 20 | H269: 365 | I269: 26 | J269: 66

Sheet blinkit_customers
A1: customer_id | B1: customer_name | C1: email | D1: phone | E1: address | F1: area | G1: pincode | H1: registration_date | I1: customer_segment | J1: total_orders | K1: avg_order_value
A2: 45383958 | B2: Aachal Mangat | C2: yasti56@example.org | D2: 917359299521 | E2: H.No. 37 Venkatesh, Sonipat-528712 | F2: Rewa | G2: 626591 | H2: 45567 | I2: New | J2: 19 | K2: 482.19
A3: 14161586 | B3: Aachal Nazareth | C3: aadhya71@example.org | D3: 919346916511 | E3: 903 Bajaj Chowk, Jaunpur-242237 | F3: Bettiah | G3: 585408 | H3: 45091 | I3: Premium | J3: 11 | K3: 353.97
A4: 15487049 | B4: Aadhya Cherian | C4: rushil71@example.com | D4: 915068387363 | E4: H.No. 071 Mane Circle Jorhat 896774 | F4: Motihari | G4: 716665 | H4: 45335 | I4: New | J4: 15 | K4: 1928
A5: 87222820 | B5: Aadhya Padmanabhan | C5: nkala@example.org | D5: 918096170656 | E5: 23/386, Savant Street, Bharatpur-396119 | F5: Ulhasnagar | G5: 651234 | H5: 45010 | I5: Inactive | J5: 13 | K5: 497.66
A6: 65618148 | B6: Aadhya Palla | C6: forumshan@example.org | D6: 915697227214 | E6: 78 Nagi Zila, Jamshedpur-811905 | F6: Gandhinagar | G6: 748222 | H6: 45014 | I6: Inactive | J6: 9 | K6: 1644.51
A7: 35885052 | B7: Aadhya Ravi | C7: urmibedi@example.org | D7: 917577557825 | E7: 20/26 Kuruvilla Road, Pondicherry-851116 | F7: Bhiwandi | G7: 745674 | H7: 45193 | I7: Inactive | J7: 1 | K7: 1838.87
A8: 79206969 | B8: Aadi Bains | C8: girindra18@example.net | D8: 916265590124 | E8: 671, Khurana Mango 598682 | F8: Jamalpur | G8: 574469 | H8: 45247 | I8: Regular | J8: 1 | K8: 721.13
A9: 10608845 | B9: Aadi Gole | C9: vbalan@example.com | D9: 918797630971 | E9: 69/876, Varughese Path Tadipatri 100656 | F9: Bhilwara | G9: 702163 | H9: 45380 | I9: Premium | J9: 2 | K9: 735.36
A10: 65692224 | B10: Aahana Buch | C10: zayyan92@example.com | D10: 916331588994 | E10: H.No. 50 Dave Marg Nashik 705135 | F10: Jaunpur | G10: 542226 | H10: 45003 | I10: Regular | J10: 3 | K10: 1053.33
A11: 44426129 | B11: Aahana Gopal | C11: tdave@example.org | D11: 911329393852 | E11: 297 Kakar Zila South Dumdum 826959 | F11: Vasai-Virar | G11: 945784 | H11: 45192 | I11: Regular | J11: 10 | K11: 591.55
A12: 75913572 | B12: Aahana Menon | C12: guhadalaja@example.com | D12: 917893263725 | E12: 652 Nori Road, Rajahmundry 374248 | F12: Guna | G12: 325080 | H12: 45377 | I12: Inactive | J12: 9 | K12: 1844.07
A13: 33998721 | B13: Aahana Naik | C13: rakshabahri@example.org | D13: 915366695062 | E13: H.No. 71, Khalsa Chowk Warangal 517087 | F13: Bhilai | G13: 702364 | H13: 45333 | I13: New | J13: 8 | K13: 245.84
... A2501: 65143359 | B2501: Zinal Thakkar | C2501: pranavdara@example.net | D2501: 916329501969 | E2501: 08 Comar Circle, Secunderabad-809728 | F2501: Bhind | G2501: 238085 | H2501: 45339 | I2501: Premium | J2501: 14 | K2501: 1071.2

Sheet blinkit_orders
A1: order_id | B1: customer_id | C1: order_date | D1: promised_delivery_time | E1: actual_delivery_time | F1: delivery_status | G1: order_total | H1: payment_method | I1: delivery_partner_id | J1: store_id | K1: delivery_time
A2: 1961864118 | B2: 30065862 | C2: 45490.357 | D2: 45490.369 | E2: 45490.366 | F2: On Time | G2: 3197.07 | H2: Cash | I2: 63230 | J2: 4771 | K2: =(E2-D2)*1440 -> -5
A3: 1549769649 | B3: 9573071 | C3: 45440.552 | D3: 45440.559 | E3: 45440.561 | F3: On Time | G3: 976.55 | H3: Cash | I3: 14983 | J3: 7534 | K3: =(E3-D3)*1440 -> 2
A4: 9185164487 | B4: 45477575 | C4: 45558.547 | D4: 45558.559 | E4: 45558.562 | F4: On Time | G4: 839.05 | H4: UPI | I4: 39859 | J4: 9886 | K4: =(E4-D4)*1440 -> 4
A5: 9644738826 | B5: 88067569 | C5: 45254.678 | D5: 45254.691 | E5: 45254.69 | F5: On Time | G5: 440.23 | H5: Card | I5: 61497 | J5: 7917 | K5: =(E5-D5)*1440 -> -1
A6: 5427684290 | B6: 83298567 | C6: 45250.209 | D6: 45250.221 | E6: 45250.221 | F6: On Time | G6: 2526.68 | H6: Cash | I6: 84315 | J6: 2741 | K6: =(E6-D6)*1440 -> 1
A7: 3265154092 | B7: 43367112 | C7: 45003.687 | D7: 45003.701 | E7: 45003.701 | F7: On Time | G7: 3161.43 | H7: UPI | I7: 554 | J7: 3442 | K7: =(E7-D7)*1440 -> -1
A8: 4898355547 | B8: 13284996 | C8: 45032.785 | D8: 45032.793 | E8: 45032.793 | F8: On Time | G8: 956.4 | H8: Card | I8: 14630 | J8: 1318 | K8: =(E8-D8)*1440 -> 1
A9: 6568151549 | B9: 88866835 | C9: 45382.269 | D9: 45382.276 | E9: 45382.278 | F9: On Time | G9: 905.47 | H9: Cash | I9: 67714 | J9: 115 | K9: =(E9-D9)*1440 -> 2
A10: 6006693867 | B10: 24496983 | C10: 45120.993 | D10: 45121.002 | E10: 45121.004 | F10: On Time | G10: 1371.17 | H10: Card | I10: 91362 | J10: 9021 | K10: =(E10-D10)*1440 -> 3
A11: 374186990 | B11: 52215833 | C11: 45147.054 | D11: 45147.068 | E11: 45147.073 | F11: Slightly Delayed | G11: 1601.19 | H11: Wallet | I11: 77203 | J11: 7955 | K11: =(E11-D11)*1440 -> 7
A12: 4455336265 | B12: 43431724 | C12: 45168.817 | D12: 45168.824 | E12: 45168.823 | F12: On Time | G12: 2362.33 | H12: UPI | I12: 64046 | J12: 3784 | K12: =(E12-D12)*1440 -> -2
A13: 3539286337 | B13: 77559557 | C13: 45041.856 | D13: 45041.864 | E13: 45041.861 | F13: On Time | G13: 1463.8 | H13: Wallet | I13: 94899 | J13: 2463 | K13: =(E13-D13)*1440 -> -5
... A5001: 2494813730 | B5001: 28663279 | C5001: 45161.503 | D5001: 45161.514 | E5001: 45161.515 | F5001: On Time | G5001: 1879.46 | H5001: Card | I5001: 32851 | J5001: 5588 | K5001: =(E5001-D5001)*1440 -> 1

Sheet Pivot Table
A3: Category | B3: Sum of order_total | F3: Payment Method | G3: Sum of order_total | J3: Customer Segment | K3: Sum of order_total
A4: Dairy & Breakfast | B4: 1244368.7 | F4: Card | G4: 2865557.5 | J4: Inactive | K4: 2591975.7
A5: Household Care | B5: 1136440.5 | F5: Cash | G5: 2770464 | J5: New | K5: 2795854.5
A6: Pet Care | B6: 1125103.8 | F6: UPI | G6: 2658282.7 | J6: Premium | K6: 2731329.7
A7: Fruits & Vegetables | B7: 1085102.8 | F7: Wallet | G7: 2715004.3 | J7: Regular | K7: 2890148.7
A8: Pharmacy | B8: 1055812 | F8: Grand Total | G8: 11009308 | J8: Grand Total | K8: 11009308
A9: Snacks & Munchies | B9: 1043581.9
A10: Grocery & Staples | B10: 1005494.9
A11: Personal Care | B11: 1003163.4
A12: Cold Drinks & Juices | B12: 828002.23
A13: Instant & Frozen Food | B13: 741183.31 | F13: Delivery_status | G13: Count of order_id | J13: Order_Date | K13: Sum of order_total
A14: Baby Care | B14: 741055.06 | F14: On Time | G14: 3470 | J14: Jan | K14: 560423.56
A15: Grand Total | B15: 11009309 | F15: Significantly Delayed | G15: 493 | J15: Feb | K15: 545090.11 | M15: Order_Date | N15: Sum of order_total
F16: Slightly Delayed | G16: 1037 | J16: Mar | K16: 816060.81 | M16: Baby Care | N16: 741055.06
A17: Total Sales | B17: =SUM(GETPIVOTDATA("order_total",$A$3)) -> 11009309 | F17: Grand Total | G17: 5000 | J17: Apr | K17: 1093099.5 | M17: Cold Drinks & Juices | N17: 828002.23
A18: Total Order | B18: =GETPIVOTDATA("order_id",$F$13) -> 5000 | J18: May | K18: 1182377.1 | M18: Dairy & Breakfast | N18: 1244368.7
A19: Avg Order Value | B19: =GETPIVOTDATA("order_total",$A$32) -> 2201.8617 | J19: Jun | K19: 1044302.5 | M19: Fruits & Vegetables | N19: 1085102.8
A20: Avg Delivery Tiime | B20: =A37 -> 4.443 | J20: Jul | K20: 1140751.9 | M20: Grocery & Staples | N20: 1005494.9
J21: Aug | K21: 1169666.9 | M21: Household Care | N21: 1136440.5
J22: Sep | K22: 1089812.8 | M22: Instant & Frozen Food | N22: 741183.31
J23: Oct | K23: 1116072.8 | M23: Personal Care | N23: 1003163.4
J24: Nov | K24: 635941.39 | M24: Pet Care | N24: 1125103.8
J25: Dec | K25: 615709.03 | M25: Pharmacy | N25: 1055812
J26: Grand Total | K26: 11009308 | M26: Snacks & Munchies | N26: 1043581.9
M27: Grand Total | N27: 11009309
G28: Product_Name | H28: Sum of order_total
G29: Cough Syrup | H29: 407824.64
G30: Dish Soap | H30: 420875.06
D31: Count of customer_id | G31: Lotion | H31: 434235.77
A32: Average of order_total | D32: 5000 | G32: Pet Treats | H32: 525666.31
A33: 2201.8617 | G33: Toilet Cleaner | H33: 434588.6
G34: Grand Total | H34: 2223190.4
A36: Average of delivery_time_(min)
A37: 4.443

Sheet Dashboard

Sheet Master data
A1: order_id | B1: customer_id | C1: customer_name | D1: customer_segment | E1: product_id | F1: product_name | G1: category | H1: quantity | I1: unit_price | J1: order_total | K1: payment_method | L1: delivery status | M1: delivery_time_(min) | N1: order_date
A2: 1961864118 | B2: 30065862 | C2: =_xlfn.XLOOKUP(B2,blinkit_customers!A:A,blinkit_customers!B:B," ") -> Urishilla Hegde | D2: =_xlfn.XLOOKUP(B2, blinkit_customers!A:A,blinkit_customers!I:I, " ") -> Regular | E2: =_xlfn.XLOOKUP(A2,blinkit_order_items[order_id],blinkit_order_items[product_id]) -> 642612 | F2: =_xlfn.XLOOKUP(E2,blinkit_products[product_id],blinkit_products[product_name]) -> Pet Treats | G2: =_xlfn.XLOOKUP(E2,blinkit_products[product_id],blinkit_products[category]) -> Pet Care | H2: =_xlfn.XLOOKUP(A2,blinkit_order_items[order_id],blinkit_order_items[quantity]) -> 3 | I2: =_xlfn.XLOOKUP(A2,blinkit_order_items[order_id],blinkit_order_items[unit_price]) -> 517.03 | J2: 3197.07 | K2: Cash | L2: On Time | M2: -5 | N2: 45490.357
A3: 1549769649 | B3: 9573071 | C3: =_xlfn.XLOOKUP(B3,blinkit_customers!A:A,blinkit_customers!B:B," ") -> Ranveer Mahal | D3: =_xlfn.XLOOKUP(B3, blinkit_customers!A:A,blinkit_customers!I:I, " ") -> New | E3: =_xlfn.XLOOKUP(A3,blinkit_order_items[order_id],blinkit_order_items[product_id]) -> 378676 | F3: =_xlfn.XLOOKUP(E3,blinkit_products[product_id],blinkit_products[product_name]) -> Orange Juice | G3: =_xlfn.XLOOKUP(E3,blinkit_products[product_id],blinkit_products[category]) -> Cold Drinks & Juices | H3: =_xlfn.XLOOKUP(A3,blinkit_order_items[order_id],blinkit_order_items[quantity]) -> 1 | I3: =_xlfn.XLOOKUP(A3,blinkit_order_items[order_id],blinkit_order_items[unit_price]) -> 881.42 | J3: 976.55 | K3: Cash | L3: On Time | M3: 2 | N3: 45440.552
A4: 9185164487 | B4: 45477575 | C4: =_xlfn.XLOOKUP(B4,blinkit_customers!A:A,blinkit_customers!B:B," ") -> Aarna Bawa | D4: =_xlfn.XLOOKUP(B4, blinkit_customers!A:A,blinkit_customers!I:I, " ") -> Inactive | E4: =_xlfn.XLOOKUP(A4,blinkit_order_items[order_id],blinkit_order_items[product_id]) -> 741341 | F4: =_xlfn.XLOOKUP(E4,blinkit_products[product_id],blinkit_products[product_name]) -> Eggs | G4: =_xlfn.XLOOKUP(E4,blinkit_products[product_id],blinkit_products[category]) -> Dairy & Breakfast | H4: =_xlfn.XLOOKUP(A4,blinkit_order_items[order_id],blinkit_order_items[quantity]) -> 2 | I4: =_xlfn.XLOOKUP(A4,blinkit_order_items[order_id],blinkit_order_items[unit_price]) -> 923.84 | J4: 839.05 | K4: UPI | L4: On Time | M4: 4 | N4: 45558.547
A5: 9644738826 | B5: 88067569 | C5: =_xlfn.XLOOKUP(B5,blinkit_customers!A:A,blinkit_customers!B:B," ") -> Aayush Sengupta | D5: =_xlfn.XLOOKUP(B5, blinkit_customers!A:A,blinkit_customers!I:I, " ") -> Premium | E5: =_xlfn.XLOOKUP(A5,blinkit_order_items[order_id],blinkit_order_items[product_id]) -> 561860 | F5: =_xlfn.XLOOKUP(E5,blinkit_products[product_id],blinkit_products[product_name]) -> Orange Juice | G5: =_xlfn.XLOOKUP(E5,blinkit_products[product_id],blinkit_products[category]) -> Cold Drinks & Juices | H5: =_xlfn.XLOOKUP(A5,blinkit_order_items[order_id],blinkit_order_items[quantity]) -> 1 | I5: =_xlfn.XLOOKUP(A5,blinkit_order_items[order_id],blinkit_order_items[unit_price]) -> 874.78 | J5: 440.23 | K5: Card | L5: On Time | M5: -1 | N5: 45254.678
A6: 5427684290 | B6: 83298567 | C6: =_xlfn.XLOOKUP(B6,blinkit_customers!A:A,blinkit_customers!B:B," ") -> Vansha Kuruvilla | D6: =_xlfn.XLOOKUP(B6, blinkit_customers!A:A,blinkit_customers!I:I, " ") -> Premium | E6: =_xlfn.XLOOKUP(A6,blinkit_order_items[order_id],blinkit_order_items[product_id]) -> 602241 | F6: =_xlfn.XLOOKUP(E6,blinkit_products[product_id],blinkit_products[product_name]) -> Nuts | G6: =_xlfn.XLOOKUP(E6,blinkit_products[product_id],blinkit_products[category]) -> Snacks & Munchies | H6: =_xlfn.XLOOKUP(A6,blinkit_order_items[order_id],blinkit_order_items[quantity]) -> 2 | I6: =_xlfn.XLOOKUP(A6,blinkit_order_items[order_id],blinkit_order_items[unit_price]) -> 976.55 | J6: 2526.68 | K6: Cash | L6: On Time | M6: 1 | N6: 45250.209
A7: 3265154092 | B7: 43367112 | C7: =_xlfn.XLOOKUP(B7,blinkit_customers!A:A,blinkit_customers!B:B," ") -> Chasmum Ramesh | D7: =_xlfn.XLOOKUP(B7, blinkit_customers!A:A,blinkit_customers!I:I, " ") -> New | E7: =_xlfn.XLOOKUP(A7,blinkit_order_items[order_id],blinkit_order_items[product_id]) -> 681063 | F7: =_xlfn.XLOOKUP(E7,blinkit_products[product_id],blinkit_products[product_name]) -> Mango Drink | G7: =_xlfn.XLOOKUP(E7,blinkit_products[product_id],blinkit_products[category]) -> Cold Drinks & Juices | H7: =_xlfn.XLOOKUP(A7,blinkit_order_items[order_id],blinkit_order_items[quantity]) -> 1 | I7: =_xlfn.XLOOKUP(A7,blinkit_order_items[order_id],blinkit_order_items[unit_price]) -> 321.28 | J7: 3161.43 | K7: UPI | L7: On Time | M7: -1 | N7: 45003.687
A8: 4898355547 | B8: 13284996 | C8: =_xlfn.XLOOKUP(B8,blinkit_customers!A:A,blinkit_customers!B:B," ") -> Irya Dayal | D8: =_xlfn.XLOOKUP(B8, blinkit_customers!A:A,blinkit_customers!I:I, " ") -> Regular | E8: =_xlfn.XLOOKUP(A8,blinkit_order_items[order_id],blinkit_order_items[product_id]) -> 56589 | F8: =_xlfn.XLOOKUP(E8,blinkit_products[product_id],blinkit_products[product_name]) -> Vitamins | G8: =_xlfn.XLOOKUP(E8,blinkit_products[product_id],blinkit_products[category]) -> Pharmacy | H8: =_xlfn.XLOOKUP(A8,blinkit_order_items[order_id],blinkit_order_items[quantity]) -> 3 | I8: =_xlfn.XLOOKUP(A8,blinkit_order_items[order_id],blinkit_order_items[unit_price]) -> 517.77 | J8: 956.4 | K8: Card | L8: On Time | M8: 1 | N8: 45032.785
A9: 6568151549 | B9: 88866835 | C9: =_xlfn.XLOOKUP(B9,blinkit_customers!A:A,blinkit_customers!B:B," ") -> Osha Dora | D9: =_xlfn.XLOOKUP(B9, blinkit_customers!A:A,blinkit_customers!I:I, " ") -> Premium | E9: =_xlfn.XLOOKUP(A9,blinkit_order_items[order_id],blinkit_order_items[product_id]) -> 500739 | F9: =_xlfn.XLOOKUP(E9,blinkit_products[product_id],blinkit_products[product_name]) -> Bread | G9: =_xlfn.XLOOKUP(E9,blinkit_products[product_id],blinkit_products[category]) -> Dairy & Breakfast | H9: =_xlfn.XLOOKUP(A9,blinkit_order_items[order_id],blinkit_order_items[quantity]) -> 2 | I9: =_xlfn.XLOOKUP(A9,blinkit_order_items[order_id],blinkit_order_items[unit_price]) -> 359.98 | J9: 905.47 | K9: Cash | L9: On Time | M9: 2 | N9: 45382.269
A10: 6006693867 | B10: 24496983 | C10: =_xlfn.XLOOKUP(B10,blinkit_customers!A:A,blinkit_customers!B:B," ") -> Vasana Sen | D10: =_xlfn.XLOOKUP(B10, blinkit_customers!A:A,blinkit_customers!I:I, " ") -> Regular | E10: =_xlfn.XLOOKUP(A10,blinkit_order_items[order_id],blinkit_order_items[product_id]) -> 490939 | F10: =_xlfn.XLOOKUP(E10,blinkit_products[product_id],blinkit_products[product_name]) -> Lotion | G10: =_xlfn.XLOOKUP(E10,blinkit_products[product_id],blinkit_products[category]) -> Personal Care | H10: =_xlfn.XLOOKUP(A10,blinkit_order_items[order_id],blinkit_order_items[quantity]) -> 1 | I10: =_xlfn.XLOOKUP(A10,blinkit_order_items[order_id],blinkit_order_items[unit_price]) -> 80.25 | J10: 1371.17 | K10: Card | L10: On Time | M10: 3 | N10: 45120.993
A11: 374186990 | B11: 52215833 | C11: =_xlfn.XLOOKUP(B11,blinkit_customers!A:A,blinkit_customers!B:B," ") -> Lipika Parmer | D11: =_xlfn.XLOOKUP(B11, blinkit_customers!A:A,blinkit_customers!I:I, " ") -> Regular | E11: =_xlfn.XLOOKUP(A11,blinkit_order_items[order_id],blinkit_order_items[product_id]) -> 760828 | F11: =_xlfn.XLOOKUP(E11,blinkit_products[product_id],blinkit_products[product_name]) -> Pet Treats | G11: =_xlfn.XLOOKUP(E11,blinkit_products[product_id],blinkit_products[category]) -> Pet Care | H11: =_xlfn.XLOOKUP(A11,blinkit_order_items[order_id],blinkit_order_items[quantity]) -> 2 | I11: =_xlfn.XLOOKUP(A11,blinkit_order_items[order_id],blinkit_order_items[unit_price]) -> 563.45 | J11: 1601.19 | K11: Wallet | L11: Slightly Delayed | M11: 7 | N11: 45147.054
A12: 4455336265 | B12: 43431724 | C12: =_xlfn.XLOOKUP(B12,blinkit_customers!A:A,blinkit_customers!B:B," ") -> Jack Kalita | D12: =_xlfn.XLOOKUP(B12, blinkit_customers!A:A,blinkit_customers!I:I, " ") -> New | E12: =_xlfn.XLOOKUP(A12,blinkit_order_items[order_id],blinkit_order_items[product_id]) -> 753354 | F12: =_xlfn.XLOOKUP(E12,blinkit_products[product_id],blinkit_products[product_name]) -> Shampoo | G12: =_xlfn.XLOOKUP(E12,blinkit_products[product_id],blinkit_products[category]) -> Personal Care | H12: =_xlfn.XLOOKUP(A12,blinkit_order_items[order_id],blinkit_order_items[quantity]) -> 3 | I12: =_xlfn.XLOOKUP(A12,blinkit_order_items[order_id],blinkit_order_items[unit_price]) -> 423.56 | J12: 2362.33 | K12: UPI | L12: On Time | M12: -2 | N12: 45168.817
A13: 3539286337 | B13: 77559557 | C13: =_xlfn.XLOOKUP(B13,blinkit_customers!A:A,blinkit_customers!B:B," ") -> Akshay Varty | D13: =_xlfn.XLOOKUP(B13, blinkit_customers!A:A,blinkit_customers!I:I, " ") -> New | E13: =_xlfn.XLOOKUP(A13,blinkit_order_items[order_id],blinkit_order_items[product_id]) -> 684939 | F13: =_xlfn.XLOOKUP(E13,blinkit_products[product_id],blinkit_products[product_name]) -> Lotion | G13: =_xlfn.XLOOKUP(E13,blinkit_products[product_id],blinkit_products[category]) -> Personal Care | H13: =_xlfn.XLOOKUP(A13,blinkit_order_items[order_id],blinkit_order_items[quantity]) -> 1 | I13: =_xlfn.XLOOKUP(A13,blinkit_order_items[order_id],blinkit_order_items[unit_price]) -> 727.95 | J13: 1463.8 | K13: Wallet | L13: On Time | M13: -5 | N13: 45041.856
... A5001: 2494813730 | B5001: 28663279 | C5001: =_xlfn.XLOOKUP(B5001,blinkit_customers!A:A,blinkit_customers!B:B," ") -> Sai Bhatia | D5001: =_xlfn.XLOOKUP(B5001, blinkit_customers!A:A,blinkit_customers!I:I, " ") -> Premium | E5001: =_xlfn.XLOOKUP(A5001,blinkit_order_items[order_id],blinkit_order_items[product_id]) -> 136533 | F5001: =_xlfn.XLOOKUP(E5001,blinkit_products[product_id],blinkit_products[product_name]) -> Eggs | G5001: =_xlfn.XLOOKUP(E5001,blinkit_products[product_id],blinkit_products[category]) -> Dairy & Breakfast | H5001: =_xlfn.XLOOKUP(A5001,blinkit_order_items[order_id],blinkit_order_items[quantity]) -> 1 | I5001: =_xlfn.XLOOKUP(A5001,blinkit_order_items[order_id],blinkit_order_items[unit_price]) -> 826.21 | J5001: 1879.46 | K5001: Card | L5001: On Time | M5001: 1 | N5001: 45161.503

Sheet Dim_Customer
A1: customer_id | B1: customer_name | C1: customer_segment
A2: 30065862 | B2: Urishilla Hegde | C2: Regular
A3: 9573071 | B3: Ranveer Mahal | C3: New
A4: 45477575 | B4: Aarna Bawa | C4: Inactive
A5: 88067569 | B5: Aayush Sengupta | C5: Premium
A6: 83298567 | B6: Vansha Kuruvilla | C6: Premium
A7: 43367112 | B7: Chasmum Ramesh | C7: New
A8: 13284996 | B8: Irya Dayal | C8: Regular
A9: 88866835 | B9: Osha Dora | C9: Premium
A10: 24496983 | B10: Vasana Sen | C10: Regular
A11: 52215833 | B11: Lipika Parmer | C11: Regular
A12: 43431724 | B12: Jack Kalita | C12: New
A13: 77559557 | B13: Akshay Varty | C13: New
... A2173: 80952275 | B2173: Kevin Babu | C2173: New

Sheet blinkit_delivery_performance 
A1: order_id | B1: delivery_partner_id | C1: promised_time | D1: actual_time | E1: delivery_time_minutes | F1: distance_km | G1: delivery_status | H1: reasons_if_delayed
A2: 1961864118 | B2: 63230 | C2: 45490.369 | D2: 45490.366 | E2: -5 | F2: 0.96 | G2: On Time
A3: 1549769649 | B3: 14983 | C3: 45440.559 | D3: 45440.56 | E3: 2 | F3: 0.98 | G3: On Time | H3: Traffic
A4: 9185164487 | B4: 39859 | C4: 45558.559 | D4: 45558.562 | E4: 4 | F4: 3.83 | G4: On Time | H4: Traffic
A5: 9644738826 | B5: 61497 | C5: 45254.69 | D5: 45254.69 | E5: -1 | F5: 2.76 | G5: On Time
A6: 5427684290 | B6: 84315 | C6: 45250.22 | D6: 45250.221 | E6: 1 | F6: 2.63 | G6: On Time | H6: Traffic
A7: 3265154092 | B7: 554 | C7: 45003.701 | D7: 45003.7 | E7: -1 | F7: 1.94 | G7: On Time
A8: 4898355547 | B8: 14630 | C8: 45032.792 | D8: 45032.793 | E8: 1 | F8: 2.2 | G8: On Time | H8: Traffic
A9: 6568151549 | B9: 67714 | C9: 45382.276 | D9: 45382.277 | E9: 2 | F9: 1.3 | G9: On Time | H9: Traffic
A10: 6006693867 | B10: 91362 | C10: 45121.001 | D10: 45121.003 | E10: 3 | F10: 3.38 | G10: On Time | H10: Traffic
A11: 374186990 | B11: 77203 | C11: 45147.067 | D11: 45147.072 | E11: 7 | F11: 1.47 | G11: Slightly Delayed | H11: Traffic
A12: 4455336265 | B12: 64046 | C12: 45168.824 | D12: 45168.823 | E12: -2 | F12: 0.76 | G12: On Time
A13: 3539286337 | B13: 94899 | C13: 45041.864 | D13: 45041.86 | E13: -5 | F13: 3.68 | G13: On Time
A14: 9171116867 | B14: 73907 | C14: 45221.476 | D14: 45221.484 | E14: 12 | F14: 2.23 | G14: Slightly Delayed | H14: Traffic
A15: 5504941865 | B15: 56077 | C15: 45319.122 | D15: 45319.129 | E15: 11 | F15: 4.45 | G15: Slightly Delayed | H15: Traffic
A16: 5868326481 | B16: 94140 | C16: 45366.892 | D16: 45366.89 | E16: -3 | F16: 2.8 | G16: On Time
A17: 2137046916 | B17: 12377 | C17: 45325.377 | D17: 45325.376 | E17: -2 | F17: 1.78 | G17: On Time
A18: 8195544338 | B18: 102 | C18: 45042.181 | D18: 45042.186 | E18: 8 | F18: 1.16 | G18: Slightly Delayed | H18: Traffic
A19: 2889700050 | B19: 45032 | C19: 45412.69 | D19: 45412.692 | E19: 3 | F19: 3.07 | G19: On Time | H19: Traffic
A20: 65827885 | B20: 1108 | C20: 45134.017 | D20: 45134.014 | E20: -5 | F20: 1.65 | G20: On Time
A21: 4656471694 | B21: 62782 | C21: 45269.352 | D21: 45269.358 | E21: 8 | F21: 3.7 | G21: Slightly Delayed | H21: Traffic
A22: 6625178717 | B22: 74906 | C22: 45108.194 | D22: 45108.203 | E22: 13 | F22: 4.22 | G22: Slightly Delayed | H22: Traffic
A23: 7169557514 | B23: 79516 | C23: 45006.235 | D23: 45006.243 | E23: 12 | F23: 3.28 | G23: Slightly Delayed | H23: Traffic
A24: 2268306684 | B24: 65733 | C24: 45440.633 | D24: 45440.632 | E24: -1 | F24: 1.82 | G24: On Time
A25: 6905293278 | B25: 53868 | C25: 45459.442 | D25: 45459.46 | E25: 26 | F25: 0.58 | G25: Significantly Delayed | H25: Traffic
A26: 1769493463 | B26: 22954 | C26: 45469.312 | D26: 45469.308 | E26: -5 | F26: 1.21 | G26: On Time
A27: 5003387344 | B27: 21004 | C27: 45466.462 | D27: 45466.458 | E27: -5 | F27: 4.52 | G27: On Time
A28: 2064484752 | B28: 43022 | C28: 45419.958 | D28: 45419.955 | E28: -5 | F28: 2.29 | G28: On Time
A29: 964822979 | B29: 42914 | C29: 45486.451 | D29: 45486.449 | E29: -2 | F29: 1.09 | G29: On Time
A30: 6037899648 | B30: 59131 | C30: 45378.75 | D30: 45378.753 | E30: 4 | F30: 4.56 | G30: On Time | H30: Traffic
A31: 9347571484 | B31: 88612 | C31: 45598.726 | D31: 45598.735 | E31: 13 | F31: 3.29 | G31: Slightly Delayed | H31: Traffic
A32: 3286177534 | B32: 90038 | C32: 45102.006 | D32: 45102.005 | E32: -2 | F32: 3.07 | G32: On Time
A33: 9073572548 | B33: 28575 | C33: 45048.976 | D33: 45048.991 | E33: 22 | F33: 4.77 | G33: Significantly Delayed | H33: Traffic
A34: 8395583761 | B34: 84816 | C34: 45508.995 | D34: 45508.992 | E34: -5 | F34: 3.53 | G34: On Time
A35: 6355378227 | B35: 23910 | C35: 45149.713 | D35: 45149.712 | E35: -1 | F35: 3.91 | G35: On Time
A36: 277376321 | B36: 78589 | C36: 45501.198 | D36: 45501.197 | E36: -1 | F36: 3.85 | G36: On Time
A37: 8559748526 | B37: 93002 | C37: 45021.769 | D37: 45021.769 | E37: 1 | F37: 0.94 | G37: On Time | H37: Traffic
A38: 1458051433 | B38: 61040 | C38: 45408.396 | D38: 45408.393 | E38: -4 | F38: 2.75 | G38: On Time
A39: 5838302640 | B39: 30907 | C39: 45058.251 | D39: 45058.256 | E39: 7 | F39: 1.7 | G39: Slightly Delayed | H39: Traffic
A40: 1380971977 | B40: 52614 | C40: 45445.556 | D40: 45445.553 | E40: -5 | F40: 4.09 | G40: On Time
...
